<?xml version="1.0" ?>
<robot name="patrol_robot">

  <link name="base_footprint"/>

  <link name="base_link">
    <inertial>
      <mass value="2"/>
      <origin xyz="0.2 0.1397 0.01" rpy="1.5708 0 -1.5708" />
      <inertia
        ixx="0.0635" ixy="0.0" ixz="0.0"
        iyy="0.0635" iyz="0.0"
        izz="0.0651"/>
    </inertial>

    <visual>
      <origin xyz="0.2 0.1397 0.01" rpy="1.5708 0 -1.5708" /> 
      <geometry>
        <mesh filename="package://robot_desc/meshes/body_link2.stl" scale="0.001 0.001 0.001"/>
      </geometry>
      <material name="white">
        <color rgba="1 1 1 1"/>
      </material>
    </visual>

    <collision>
      <geometry>
        <mesh filename="package://robot_desc/meshes/body_link2.stl" scale="0.001 0.001 0.001"/>
    </geometry>
      <contact_coefficients mu="1" mu2="1" kp="1e+13.0" kd="1.0"/>
    </collision>
  </link>

  <joint name="base_joint" type="fixed">
      <parent link="base_footprint"/>
      <child link="base_link"/>
      <origin xyz="0 0 0.04" rpy="0 0 0"/>
  </joint>

  <link name="weight">
    <inertial>
      <mass value="7"/>
      <inertia ixx="0.03225" ixy="0.0"  ixz="0.0" iyy="0.03225" iyz="0.0" izz="0.02764"/>
      <origin xyz="0 0 0" rpy="0 0 0"/>
    </inertial>
    <visual>
        <geometry>
            <cylinder length="0.1778" radius="0.0889" />
        </geometry>
    </visual>
    <collision>
        <geometry>
            <cylinder length="0.1778" radius="0.0889" />
        </geometry>
    </collision>    
  </link>
  <joint name="weight_joint" type="fixed">
      <parent link="base_footprint"/>
      <child link="weight"/>
      <origin xyz="0 0 0.25" rpy="0 0 0"/>
  </joint>

  <link name="wheel_right">
    <inertial>
      <mass value="0.75"/>
      <inertia ixx="0.001444223" iyy="0.00280875" izz="0.001444223" ixy="0.0" ixz="0.0" iyz="0.0"/>
      <origin xyz="0 0 0" rpy="0 0 0"/>
    </inertial>
    <visual>
        <geometry>
          <cylinder length="0.04" radius="0.06858" />
        </geometry>
    </visual>
    <collision>
        <geometry>
          <cylinder length="0.04" radius="0.06858" />
        </geometry>
    </collision>      
  </link>   
  
  <joint name="wheel_right_joint" type="continuous">
    <origin xyz="0.042 0.16 0.04  " rpy="1.5708 0.0 0.0"/>
    <parent link="base_link"/>
    <child link="wheel_right"/>
    <axis xyz="0.0 0 1"/>
  </joint>

  <link name="wheel_left">
    <inertial>
      <mass value="0.75"/>
      <inertia ixx="0.001444223" iyy="0.00280875" izz="0.001444223" ixy="0.0" ixz="0.0" iyz="0.0" />
      <origin xyz="0 0 0" rpy="0 0 0"/>
    </inertial>
    <visual>
        <geometry>
            <cylinder length="0.04" radius="0.06858" />
        </geometry>
    </visual>
    <collision>
        <geometry>
            <cylinder length="0.04" radius="0.06858" />
        </geometry>
    </collision>    
  </link>
  
  <joint name="wheel_left_joint" type="continuous">
    <origin xyz="0.042 -0.16 0.04" rpy="1.5708 0.0 3.14"/>
    <parent link="base_link"/>
    <child link="wheel_left"/>
    <axis xyz="0.0 0 1"/>
  </joint>
  
  
  <link name="caster">
    <inertial>
      <mass value="1.5"/>
      <inertia ixx="0.0001295" iyy="0.0001295" izz="0.000199322" ixy="0.0" ixz="0.0" iyz="0.0" />
      <origin/>
    </inertial>

    <visual>
      <geometry>
        <mesh filename="package://robot_desc/meshes/front_caster.stl"/>
      </geometry>
      <material name="white">
        <color rgba="1 1 1 1"/>
      </material>
    </visual>

    <collision>
      <geometry>
        <mesh filename="package://robot_desc/meshes/front_caster.stl"/>
      </geometry>
      <contact_coefficients mu="0" kp="1000.0" kd="1.0"/>
    </collision>
  </link>
  
  <joint name="caster_joint" type="continuous">
    <origin xyz="-0.0635 0 -0.01" rpy="0.0 0.0 0.0"/>
    <axis xyz="0 0 1" />
    <parent link="base_link"/>
    <child link="caster"/>
  </joint>  

  <link name="camera_link">
  </link>

  <joint name="camera_joint" type="fixed">
    <origin xyz="-0.16 0.0 0.08" rpy="0 0.0 3.14"/>
    <parent link="base_link"/>
    <child link="camera_link"/>
    <axis xyz="0.0 0.0 1.0"/>
  </joint>

  <gazebo reference="camera_link">
      <sensor type="camera" name="Botcamera">
        <update_rate>30.0</update_rate>
        <camera name="head">
          <horizontal_fov>1.3962634</horizontal_fov>
          <image>
            <width>800</width>
            <height>800</height>
            <format>R8G8B8</format>
          </image>
          <clip>
            <near>0.02</near>
            <far>300</far>
          </clip>
          <noise>
            <type>gaussian</type>
            <mean>0.0</mean>
            <stddev>0.007</stddev>
          </noise>
        </camera>
        <plugin name="camera_controller" filename="libgazebo_ros_camera.so">
          <alwaysOn>true</alwaysOn>
          <updateRate>0.0</updateRate>
          <cameraName>/Botcamera</cameraName>
          <imageTopicName>image_raw</imageTopicName>
          <cameraInfoTopicName>camera_info</cameraInfoTopicName>
          <frameName>camera_link</frameName>
          <hackBaseline>0.07</hackBaseline>
        </plugin>
      </sensor>
      <material>Gazebo/Blue</material>
  </gazebo>

  <joint name="imu_joint" type="fixed">
    <parent link="base_footprint"/>
    <child link="imu_link"/>
    <origin xyz="0.0 0 0" rpy="0 0 0"/>
  </joint>

  <link name="imu_link"/>

  <link name="lidar_link">
    <visual>
        <origin xyz="0 -0.0009 -0.011" rpy="1.5708 0 -1.5708"/>
        <geometry>
            <mesh filename="package://robot_desc/meshes/rplidar.dae" scale="0.001 0.001 0.001"/>
        </geometry>
    </visual> 
    <collision>
        <origin xyz="0 -0.0028 0" rpy="0 0 0"/>
        <geometry>
            <cylinder radius="0.037" length="0.021"/>
        </geometry>
    </collision>
    <inertial>
      <mass value="0.07"/>
      <origin xyz="0 0 0" rpy="0 0 0"/>
      <inertia 
        ixx="0.000262" ixy="0.0" ixz="0.0" 
        iyy="0.000262" iyz="0.0" 
        izz="0.000048"/>
    </inertial>
  </link>

  <joint name="lidar_joint" type="fixed">
      <parent link="base_link"/>
      <child link="lidar_link"/>
      <origin xyz="0 0 0.77" rpy="0 0 0"/>
      <axis xyz="0 0 1"/>
  </joint>

  <gazebo reference="lidar_link">
      <sensor name="lidar" type="ray">
          <pose>0 0 0 0 0 0</pose>
          <always_on>true</always_on>
          <visualize>false</visualize>
          <update_rate>10</update_rate>
          <ray>
              <scan>
                  <horizontal>
                      <samples>360</samples>
                      <min_angle>-3.14</min_angle>
                      <max_angle>3.14</max_angle>
                  </horizontal>
              </scan>
              <range>
                  <min>0.15</min>
                  <max>6.0</max>
                  <!-- <max>12.0</max> -->
                  <resolution>0.01500</resolution>
          </range>
              <noise>
                  <type>gaussian</type>
                  <mean>0.0</mean>
                  <stddev>0.01</stddev>
              </noise>
          </ray>
          <plugin name="lidar_controller" filename="libgazebo_ros_ray_sensor.so">
              <ros>
              <remapping>~/out:=scan</remapping>
              </ros>
              <output_type>sensor_msgs/LaserScan</output_type>
              <frame_name>lidar_link</frame_name>
          </plugin>
      </sensor>
  </gazebo>

  <gazebo>
    <plugin filename="libgazebo_ros_diff_drive.so" name="gazebo_base_controller">
      <odometry_frame>odom</odometry_frame>
      <commandTopic>cmd_vel</commandTopic>
      <publish_odom>true</publish_odom>
      <publish_odom_tf>true</publish_odom_tf>
      <update_rate>15.0</update_rate>
      <left_joint>wheel_left_joint</left_joint>
      <right_joint>wheel_right_joint</right_joint>
      <wheel_separation>0.8</wheel_separation>
      <wheel_diameter>0.3</wheel_diameter>
      <max_wheel_acceleration>0.7</max_wheel_acceleration>
      <robotBaseFrame>base_link</robotBaseFrame>

    </plugin>
  </gazebo>


  <gazebo reference="base_link">
    <material>Gazebo/Gray</material>
  </gazebo>
  <gazebo reference="caster">
    <material>Gazebo/White</material>
  </gazebo>
  
  <gazebo reference="wheel_right">
    <material>Gazebo/Orange</material>
  </gazebo>
  <gazebo reference="wheel_left">
    <material>Gazebo/Orange</material>
  </gazebo>  

  <ros2_control name="robot_hardware" type="system">
      <hardware>
          <plugin>diffdrive_arduino/DiffDriveArduinoHardware</plugin>
              <param name="wheel_left_name">wheel_left_joint</param>
              <param name="wheel_right_name">wheel_right_joint</param>
              <param name="loop_rate">30</param>
              <param name="device">/dev/ttyAMA0</param>
              <param name="baud_rate">9600</param>
      </hardware>
      <joint name="wheel_left_joint">
          <command_interface name="velocity"/>
          <state_interface name="position"/>
          <state_interface name="velocity"/>
      </joint>
      <joint name="wheel_right_joint">
          <command_interface name="velocity"/>
          <state_interface name="position"/>
          <state_interface name="velocity"/>
      </joint>
  </ros2_control>

  <transmission name="wheel_left_trans">
    <type>transmission_interface/SimpleTransmission</type>
    <joint name="wheel_left_joint">
      <hardwareInterface>hardware_interface/VelocityJointInterface</hardwareInterface>
    </joint>
    <actuator name="wheel_left_motor">
      <hardwareInterface>hardware_interface/VelocityJointInterface</hardwareInterface>
      <mechanicalReduction>1</mechanicalReduction>
    </actuator>
  </transmission>

  <transmission name="wheel_right_trans">
    <type>transmission_interface/SimpleTransmission</type>
    <joint name="wheel_right_joint">
      <hardwareInterface>hardware_interface/VelocityJointInterface</hardwareInterface>
    </joint>
    <actuator name="wheel_right_motor">
      <hardwareInterface>hardware_interface/VelocityJointInterface</hardwareInterface>
      <mechanicalReduction>1</mechanicalReduction>
    </actuator>
  </transmission>

</robot>
  